 * Serving Flask app "todo_app/app" (lazy loading)
 * Environment: development
 * Debug mode: on
 * Running on http://0.0.0.0:5000/ (Press CTRL+C to quit)
 * Restarting with stat
 * Debugger is active!
 * Debugger PIN: 159-308-278
10.0.2.2 - - [15/Sep/2021 13:55:55] "[35m[1mGET / HTTP/1.1[0m" 500 -
Traceback (most recent call last):
  File "/home/vagrant/.pyenv/versions/3.9.0/lib/python3.9/json/decoder.py", line 353, in raw_decode
    obj, end = self.scan_once(s, idx)
StopIteration: 0

During handling of the above exception, another exception occurred:

Traceback (most recent call last):
  File "/vagrant/.venv/lib/python3.9/site-packages/flask/app.py", line 2464, in __call__
    return self.wsgi_app(environ, start_response)
  File "/vagrant/.venv/lib/python3.9/site-packages/flask/app.py", line 2450, in wsgi_app
    response = self.handle_exception(e)
  File "/vagrant/.venv/lib/python3.9/site-packages/flask/app.py", line 1867, in handle_exception
    reraise(exc_type, exc_value, tb)
  File "/vagrant/.venv/lib/python3.9/site-packages/flask/_compat.py", line 39, in reraise
    raise value
  File "/vagrant/.venv/lib/python3.9/site-packages/flask/app.py", line 2447, in wsgi_app
    response = self.full_dispatch_request()
  File "/vagrant/.venv/lib/python3.9/site-packages/flask/app.py", line 1952, in full_dispatch_request
    rv = self.handle_user_exception(e)
  File "/vagrant/.venv/lib/python3.9/site-packages/flask/app.py", line 1821, in handle_user_exception
    reraise(exc_type, exc_value, tb)
  File "/vagrant/.venv/lib/python3.9/site-packages/flask/_compat.py", line 39, in reraise
    raise value
  File "/vagrant/.venv/lib/python3.9/site-packages/flask/app.py", line 1950, in full_dispatch_request
    rv = self.dispatch_request()
  File "/vagrant/.venv/lib/python3.9/site-packages/flask/app.py", line 1936, in dispatch_request
    return self.view_functions[rule.endpoint](**req.view_args)
  File "/vagrant/todo_app/app.py", line 24, in index
    items = trelloItems.get_items()
  File "/vagrant/todo_app/data/trello_items.py", line 55, in get_items
    responseJson = make_get_request(url, query)
  File "/vagrant/todo_app/data/trello_items.py", line 95, in make_get_request
    return response.json()
  File "/vagrant/.venv/lib/python3.9/site-packages/requests/models.py", line 900, in json
    return complexjson.loads(self.text, **kwargs)
  File "/home/vagrant/.pyenv/versions/3.9.0/lib/python3.9/json/__init__.py", line 346, in loads
    return _default_decoder.decode(s)
  File "/home/vagrant/.pyenv/versions/3.9.0/lib/python3.9/json/decoder.py", line 337, in decode
    obj, end = self.raw_decode(s, idx=_w(s, 0).end())
  File "/home/vagrant/.pyenv/versions/3.9.0/lib/python3.9/json/decoder.py", line 355, in raw_decode
    raise JSONDecodeError("Expecting value", s, err.value) from None
json.decoder.JSONDecodeError: Expecting value: line 1 column 1 (char 0)
10.0.2.2 - - [15/Sep/2021 13:55:55] "[37mGET /?__debugger__=yes&cmd=resource&f=style.css HTTP/1.1[0m" 200 -
10.0.2.2 - - [15/Sep/2021 13:55:55] "[37mGET /?__debugger__=yes&cmd=resource&f=debugger.js HTTP/1.1[0m" 200 -
10.0.2.2 - - [15/Sep/2021 13:55:55] "[37mGET /?__debugger__=yes&cmd=resource&f=jquery.js HTTP/1.1[0m" 200 -
10.0.2.2 - - [15/Sep/2021 13:55:55] "[37mGET /?__debugger__=yes&cmd=resource&f=ubuntu.ttf HTTP/1.1[0m" 200 -
10.0.2.2 - - [15/Sep/2021 13:55:56] "[37mGET /?__debugger__=yes&cmd=resource&f=console.png HTTP/1.1[0m" 200 -
10.0.2.2 - - [15/Sep/2021 13:55:56] "[37mGET /?__debugger__=yes&cmd=resource&f=console.png HTTP/1.1[0m" 200 -
